<?xml version="1.0" encoding="utf-8"?>
<robot
  name="Tianji_Revo3_Left">
<link
    name="Base_L">
    <inertial>
      <origin
        xyz="0.00032267 4.798E-05 0.04066353"
        rpy="0 0 0" />
      <mass
        value="1.1962" />
      <inertia
        ixx="0.00107329"
        ixy="-1.68E-06"
        ixz="-1.05E-05"
        iyy="0.00107003"
        iyz="-3.43E-06"
        izz="0.00127315" />
    </inertial>
    <visual>
      <origin
        xyz="0 0 0"
        rpy="0 0 0" />
      <geometry>
        <mesh
          filename="../meshes/Base_L.STL" />
      </geometry>
    </visual>
    <collision>
      <origin
        xyz="0 0 0"
        rpy="0 0 0" />
      <geometry>
        <mesh
          filename="../meshes/Base_L.STL" />
      </geometry>
    </collision>
  </link>
  <link
    name="Link1_L">
    <inertial>
      <origin
        xyz="0.00002347 0.00557150 -0.03075998"
        rpy="0 0 0" />
      <mass
        value="1.9705" />
      <inertia
        ixx="0.00492293"
        ixy="0.00000550"
        ixz="0.00000193"
        iyy="0.00526513"
        iyz="0.00033232"
        izz="0.00188107" />
    </inertial>
    <visual>
      <origin
        xyz="0 0 0"
        rpy="0 0 0" />
      <geometry>
        <mesh
          filename="../meshes/Link1_L.STL" />
      </geometry>
    </visual>
    <collision>
      <origin
        xyz="0 0 0"
        rpy="0 0 0" />
      <geometry>
        <mesh
          filename="../meshes/Link1_L.STL" />
      </geometry>
    </collision>
  </link>
  <joint
    name="Joint1_L"
    type="revolute">
    <origin
      xyz="0 0 0.1745"
      rpy="0 0 2.9367" />
    <parent
      link="Base_L" />
    <child
      link="Link1_L" />
    <axis
      xyz="0 0 1" />
    <limit
      lower="-3.1067"
      upper="3.1067"
      effort="300"
      velocity="3.1416" />
  </joint>
  <link
    name="Link2_L">
    <inertial>
      <origin
        xyz="0.00013483 0.06170460 0.00950639"
        rpy="0 0 0" />
      <mass
        value="2.24398" />
      <inertia
        ixx="0.01194933"
        ixy="0.00000336"
        ixz="0.00000091"
        iyy="0.00361581"
        iyz="-0.00132804"
        izz="0.01098356" />
    </inertial>
    <visual>
      <origin
        xyz="0 0 0"
        rpy="0 0 0" />
      <geometry>
        <mesh
          filename="../meshes/Link2_L.STL" />
      </geometry>
    </visual>
    <collision>
      <origin
        xyz="0 0 0"
        rpy="0 0 0" />
      <geometry>
        <mesh
          filename="../meshes/Link2_L.STL" />
      </geometry>
    </collision>
  </link>
  <joint
    name="Joint2_L"
    type="revolute">
    <origin
      xyz="0 0 0"
      rpy="1.5708 -1.5708 0" />
    <parent
      link="Link1_L" />
    <child
      link="Link2_L" />
    <axis
      xyz="0 0 1" />
    <limit
      lower="-2.0944"
      upper="2.0944"
      effort="300"
      velocity="3.1416" />
  </joint>
  <link
    name="Link3_L">
    <inertial>
      <origin
        xyz="0.00968562 0.00246599 -0.04627302"
        rpy="0 0 0" />
      <mass
        value="1.9242" />
      <inertia
        ixx="0.00718224"
        ixy="0.00004413"
        ixz="0.00089552"
        iyy="0.00762563"
        iyz="0.00022096"
        izz="0.00178597" />
    </inertial>
    <visual>
      <origin
        xyz="0 0 0"
        rpy="0 0 0" />
      <geometry>
        <mesh
          filename="../meshes/Link3_L.STL" />
      </geometry>
    </visual>
    <collision>
      <origin
        xyz="0 0 0"
        rpy="0 0 0" />
      <geometry>
        <mesh
          filename="../meshes/Link3_L.STL" />
      </geometry>
    </collision>
  </link>
  <joint
    name="Joint3_L"
    type="revolute">
    <origin
      xyz="0 0.287 0"
      rpy="-1.5708 1.5708 0" />
    <parent
      link="Link2_L" />
    <child
      link="Link3_L" />
    <axis
      xyz="0 0 1" />
    <limit
      lower="-3.1067"
      upper="3.1067"
      effort="300"
      velocity="3.1416" />
  </joint>
  <link
    name="Link4_L">
    <inertial>
      <origin
        xyz="0.00850411 -0.04718223 0.00941509"
        rpy="0 0 0" />
      <mass
        value="1.6085" />
      <inertia
        ixx="0.00580480"
        ixy="-0.00066669"
        ixz="-0.00012722"
        iyy="0.00223807"
        iyz="0.00070523"
        izz="0.00533060" />
    </inertial>
    <visual>
      <origin
        xyz="0 0 0"
        rpy="0 0 0" />
      <geometry>
        <mesh
          filename="../meshes/Link4_L.STL" />
      </geometry>
    </visual>
    <collision>
      <origin
        xyz="0 0 0"
        rpy="0 0 0" />
      <geometry>
        <mesh
          filename="../meshes/Link4_L.STL" />
      </geometry>
    </collision>
  </link>
  <joint
    name="Joint4_L"
    type="revolute">
    <origin
      xyz="0.018 0 0"
      rpy="-1.5708 -1.5708 3.1416" />
    <parent
      link="Link3_L" />
    <child
      link="Link4_L" />
    <axis
      xyz="0 0 1" />
    <limit
      lower="-0.9599"
      upper="2.618"
      effort="300"
      velocity="3.1416" />
  </joint>
  <link
    name="Link5_L">
    <inertial>
      <origin
        xyz="0.00051127 0.00101064 -0.11271739"
        rpy="0 0 0" />
      <mass
        value="2.0883" />
      <inertia
        ixx="0.00626603"
        ixy="0.00004009"
        ixz="0.00005338"
        iyy="0.00564387"
        iyz="-0.00006193"
        izz="0.00243632" />
    </inertial>
    <visual>
      <origin
        xyz="0 0 0"
        rpy="0 0 0" />
      <geometry>
        <mesh
          filename="../meshes/Link5_L.STL" />
      </geometry>
    </visual>
    <collision>
      <origin
        xyz="0 0 0"
        rpy="0 0 0" />
      <geometry>
        <mesh
          filename="../meshes/Link5_L.STL" />
      </geometry>
    </collision>
  </link>
  <joint
    name="Joint5_L"
    type="revolute">
    <origin
      xyz="0.018 -0.314 0"
      rpy="-1.5708 0.5 3.1416" />
    <parent
      link="Link4_L" />
    <child
      link="Link5_L" />
    <axis
      xyz="0 0 1" />
    <limit
      lower="-3.1067"
      upper="3.1067"
      effort="100"
      velocity="3.1416" />
  </joint>
  <link
    name="Link6_L">
    <inertial>
      <origin
        xyz="0.00032659 0.00531336 -0.00030182"
        rpy="0 0 0" />
      <mass
        value="0.72496" />
      <inertia
        ixx="0.00046040"
        ixy="0.00000189"
        ixz="0.00000083"
        iyy="0.00051716"
        iyz="-0.00000346"
        izz="0.00042521" />
    </inertial>
    <visual>
      <origin
        xyz="0 0 0"
        rpy="0 0 0" />
      <geometry>
        <mesh
          filename="../meshes/Link6_L.STL" />
      </geometry>
    </visual>
    <collision>
      <origin
        xyz="0 0 0"
        rpy="0 0 0" />
      <geometry>
        <mesh
          filename="../meshes/Link6_L.STL" />
      </geometry>
    </collision>
  </link>
  <joint
    name="Joint6_L"
    type="revolute">
    <origin
      xyz="0 0 0"
      rpy="1.5708 -1.5708 0" />
    <parent
      link="Link5_L" />
    <child
      link="Link6_L" />
    <axis
      xyz="0 0 1" />
    <limit
      lower="-1.0472"
      upper="1.0472"
      effort="100"
      velocity="3.1416" />
  </joint>
  <link
    name="Link7_L">
    <inertial>
      <origin
        xyz="-0.00009108 -0.03153255 0.00889371"
        rpy="0 0 0" />
      <mass
        value="0.68606" />
      <inertia
        ixx="0.00173687"
        ixy="-0.00000345"
        ixz="-0.00000116"
        iyy="0.00089035"
        iyz="0.00030680"
        izz="0.00139406" />
    </inertial>
    <visual>
      <origin
        xyz="0 0 0"
        rpy="0 0 0" />
      <geometry>
        <mesh
          filename="../meshes/Link7_L.STL" />
      </geometry>
    </visual>
    <collision>
      <origin
        xyz="0 0 0"
        rpy="0 0 0" />
      <geometry>
        <mesh
          filename="../meshes/Link7_L.STL" />
      </geometry>
    </collision>
  </link>
  <joint
    name="Joint7_L"
    type="revolute">
    <origin
      xyz="0 0 0"
      rpy="1.5708 -1.5708 0" />
    <parent
      link="Link6_L" />
    <child
      link="Link7_L" />
    <axis
      xyz="0 0 1" />
    <limit
      lower="-1.5708"
      upper="1.5708"
      effort="100"
      velocity="3.1416" />
  </joint>

  <joint
    name="left_hand_fixed_joint_L"
    type="fixed">
    <origin
      xyz="0 -0.095 0"
      rpy="0 -1.57 1.57" />
    <parent
      link="Link7_L" />
    <child
      link="left_hand_base_link" />
  </joint>
  <link name="left_palm">
    <inertial>
      <origin xyz="0 0 0" rpy="0 0 0"/>
      <mass value="0.001"/>
      <inertia ixx="0.000001" ixy="0" ixz="0" iyy="0.000001" iyz="0" izz="0.000001"/>
    </inertial>
  </link>
  <joint name="left_palm_center" type="fixed">
    <parent link="left_hand_base_link"/>
    <child link="left_palm"/>
    <origin rpy="0 0 0" xyz="0.018 0.0 0.065"/>
  </joint>




<link
    name="left_hand_base_link">
    <inertial>
      <origin
        xyz="-0.00345743944883275 -0.000537382301113343 0.0398362805417211"
        rpy="0 0 0" />
      <mass
        value="0.462" />
      <inertia
        ixx="0.00018547"
        ixy="0.00004412"
        ixz="-0.00000603"
        iyy="0.00019776"
        iyz="0.00001828"
        izz="0.00030560" />
    </inertial>
    <visual>
      <origin
        xyz="0 0 0"
        rpy="0 0 0" />
      <geometry>
        <mesh
          filename="../meshes/left_hand_base_link.STL" />
      </geometry>
    </visual>
    <collision>
      <origin
        xyz="0 0 0"
        rpy="0 0 0" />
      <geometry>
        <mesh
          filename="../meshes/collision/left_hand_left_base_collision_link.STL" />
      </geometry>
    </collision>
  </link>
  <link
    name="left_thumb_CMP_Link">
    <inertial>
      <origin
        xyz="0.00641115513591113 0.000267351722050002 0.00107777184548508"
        rpy="0 0 0" />
      <mass
        value="0.026" />
      <inertia
        ixx="0.00000084"
        ixy="0"
        ixz="0"
        iyy="0.00000084"
        iyz="0"
        izz="0.00000084" />
    </inertial>
    <visual>
      <origin
        xyz="0 0 0"
        rpy="0 0 0" />
      <geometry>
        <mesh
          filename="../meshes/left_hand_right_thumb_CMP_Link.STL" />
      </geometry>
    </visual>
    <collision>
      <origin
        xyz="0 0 0"
        rpy="0 0 0" />
      <geometry>
        <mesh
          filename="../meshes/collision/left_hand_left_thumb_CMP_collision_Link.STL" />
      </geometry>
    </collision>
  </link>
  <joint
    name="left_thumb_CMP_joint"
    type="revolute">
    <origin
      xyz="0.002 -0.0195 0.051993"
      rpy="0 0 0" />
    <parent
      link="left_hand_base_link" />
    <child
      link="left_thumb_CMP_Link" />
    <axis
      xyz="0 0 -1" />
    <limit
      lower="-1.919863"
      upper="0"
      effort="1"
      velocity="10" />
  </joint>
  <link
    name="left_thumb_CMR_Link">
    <inertial>
      <origin
        xyz="3.15860660122461E-07 -0.006015243100639 -0.0012867270486441"
        rpy="0 0 0" />
      <mass
        value="0.012" />
      <inertia
        ixx="0.00000039"
        ixy="0"
        ixz="0"
        iyy="0.00000039"
        iyz="0"
        izz="0.00000039" />
    </inertial>
    <visual>
      <origin
        xyz="0 0 0"
        rpy="0 0 0" />
      <geometry>
        <mesh
          filename="../meshes/left_hand_right_thumb_CMR_Link.STL" />
      </geometry>
    </visual>
    <collision>
      <origin
        xyz="0 0 0"
        rpy="0 0 0" />
      <geometry>
        <mesh
          filename="../meshes/collision/left_hand_left_thumb_CMR_collision_Link.STL" />
      </geometry>
    </collision>
  </link>
  <joint
    name="left_thumb_CMR_joint"
    type="revolute">
    <origin
      xyz="0 -0.0095 0"
      rpy="0 0 0" />
    <parent
      link="left_thumb_CMP_Link" />
    <child
      link="left_thumb_CMR_Link" />
    <axis
      xyz="0 -1 0" />
    <limit
      lower="-1.5708"
      upper="0.5236"
      effort="1"
      velocity="10" />
  </joint>
  <link
    name="left_thumb_MCP_Link">
    <inertial>
      <origin
        xyz="1.26367727177707E-05 -0.0220089953181736 -0.0023377361730924"
        rpy="0 0 0" />
      <mass
        value="0.067" />
      <inertia
        ixx="0.00000595"
        ixy="0"
        ixz="0"
        iyy="0.00000687"
        iyz="0"
        izz="0.00000761" />
    </inertial>
    <visual>
      <origin
        xyz="0 0 0"
        rpy="0 0 0" />
      <geometry>
        <mesh
          filename="../meshes/left_hand_right_thumb_MCP_Link.STL" />
      </geometry>
    </visual>
    <collision>
      <origin
        xyz="0 0 0"
        rpy="0 0 0" />
      <geometry>
        <mesh
          filename="../meshes/collision/left_hand_left_thumb_MCP_collision_Link.STL" />
      </geometry>
    </collision>
  </link>
  <joint
    name="left_thumb_MCP_joint"
    type="revolute">
    <origin
      xyz="0 -0.0125 0"
      rpy="0 0 0" />
    <parent
      link="left_thumb_CMR_Link" />
    <child
      link="left_thumb_MCP_Link" />
    <axis
      xyz="-1 0 0" />
    <limit
      lower="0"
      upper="1.3265"
      effort="1"
      velocity="10" />
  </joint>
  <link
    name="left_thumb_PIP_Link">
    <inertial>
      <origin
        xyz="0.000127335211969569 -0.019664455543765 -0.000958598872046003"
        rpy="0 0 0" />
      <mass
        value="0.035" />
      <inertia
        ixx="0.00000253"
        ixy="0"
        ixz="0"
        iyy="0.00000268"
        iyz="0"
        izz="0.00000257" />
    </inertial>
    <visual>
      <origin
        xyz="0 0 0"
        rpy="0 0 0" />
      <geometry>
        <mesh
          filename="../meshes/left_hand_right_thumb_PIP_Link.STL" />
      </geometry>
    </visual>
    <collision>
      <origin
        xyz="0 0 0"
        rpy="0 0 0" />
      <geometry>
        <mesh
          filename="../meshes/collision/left_hand_left_thumb_PIP_collision_Link.STL" />
      </geometry>
    </collision>
  </link>
  <joint
    name="left_thumb_PIP_joint"
    type="revolute">
    <origin
      xyz="0 -0.042087 -0.0013667"
      rpy="0 0 0" />
    <parent
      link="left_thumb_MCP_Link" />
    <child
      link="left_thumb_PIP_Link" />
    <axis
      xyz="-1 0 0" />
    <limit
      lower="-0.17453"
      upper="1.570797"
      effort="1"
      velocity="10" />
  </joint>
  <link
    name="left_thumb_DIP_Link">
    <inertial>
      <origin
        xyz="-0.00505286358624394 0.0855834065849592 0.0497122893892139"
        rpy="0 0 0" />
      <mass
        value="0.01" />
      <inertia
        ixx="0.00000048"
        ixy="-0.00000004"
        ixz="0"
        iyy="0.00000064"
        iyz="0"
        izz="0.00000057" />
    </inertial>
    <visual>
      <origin
        xyz="0 0 0"
        rpy="0 0 0" />
      <geometry>
        <mesh
          filename="../meshes/left_hand_right_thumb_DIP_Link.STL" />
      </geometry>
    </visual>
    <collision>
      <origin
        xyz="0 0 0"
        rpy="0 0 0" />
      <geometry>
        <mesh
          filename="../meshes/collision/left_hand_left_thumb_DIP_collision_Link.STL" />
      </geometry>
    </collision>
  </link>
  <joint
    name="left_thumb_DIP_joint"
    type="revolute">
    <origin
      xyz="0 -0.031985 -0.00087263"
      rpy="0 0 0" />
    <parent
      link="left_thumb_PIP_Link" />
    <child
      link="left_thumb_DIP_Link" />
    <axis
      xyz="-1 0 0" />
    <limit
      lower="-0.17453"
      upper="1.5708"
      effort="1"
      velocity="10" />
  </joint>
  <link
    name="left_thumb_tip_Link">
    <inertial>
      <origin
        xyz="0.000225000000625279 2.09906551112971E-06 1.31450035339292E-07"
        rpy="0 0 0" />
      <mass
        value="5.23598775598299E-07" />
      <inertia
        ixx="0.00000001"
        ixy="0"
        ixz="0"
        iyy="0.00000001"
        iyz="-0.00000004"
        izz="0.00000064" />
    </inertial>
    <visual>
      <origin
        xyz="0 0 0"
        rpy="0 0 0" />
      <geometry>
        <mesh
          filename="../meshes/left_hand_right_thumb_tip_Link.STL" />
      </geometry>
    </visual>
    <!-- <collision>
      <origin
        xyz="0 0 0"
        rpy="0 0 0" />
      <geometry>
        <mesh
          filename="../meshes/left_hand_right_thumb_tip_Link.STL" />
      </geometry>
    </collision> -->
  </link>
  <joint
    name="left_thumb_tip_joint"
    type="fixed">
    <origin
      xyz="0 -0.034953 -0.0019686"
      rpy="0 0 0" />
    <parent
      link="left_thumb_DIP_Link" />
    <child
      link="left_thumb_tip_Link" />
    <axis
      xyz="0 0 0" />
  </joint>
  <link
    name="left_index_MPR_Link">
    <inertial>
      <origin
        xyz="-0.00223226880657425 -0.000719495749197045 0.00541668348184994"
        rpy="0 0 0" />
      <mass
        value="0.013" />
      <inertia
        ixx="0.00000042"
        ixy="0"
        ixz="0"
        iyy="0.00000042"
        iyz="0"
        izz="0.00000042" />
    </inertial>
    <visual>
      <origin
        xyz="0 0 0"
        rpy="0 0 0" />
      <geometry>
        <mesh
          filename="../meshes/left_hand_right_index_MPR_Link.STL" />
      </geometry>
    </visual>
    <collision>
      <origin
        xyz="0 0 0"
        rpy="0 0 0" />
      <geometry>
        <mesh
          filename="../meshes/collision/left_hand_left_index_MPR_collision_Link.STL" />
      </geometry>
    </collision>
  </link>
  <joint
    name="left_index_MPR_joint"
    type="revolute">
    <origin
      xyz="-0.005442 -0.036871 0.097822"
      rpy="0 0 0" />
    <parent
      link="left_hand_base_link" />
    <child
      link="left_index_MPR_Link" />
    <axis
      xyz="-0.99836 0.057297 0" />
    <limit
      lower="-0.2618"
      upper="0.2618"
      effort="1"
      velocity="10" />
  </joint>
  <link
    name="left_index_MCP_Link">
    <inertial>
      <origin
        xyz="-2.41253644256969E-05 -0.00140942717459576 0.0229088913305983"
        rpy="0 0 0" />
      <mass
        value="0.0658" />
      <inertia
        ixx="0.00001164"
        ixy="0.00000049"
        ixz="0.00000001"
        iyy="0.00000376"
        iyz="0"
        izz="0.00001192" />
    </inertial>
    <visual>
      <origin
        xyz="0 0 0"
        rpy="0 0 0" />
      <geometry>
        <mesh
          filename="../meshes/left_hand_right_index_MCP_Link.STL" />
      </geometry>
    </visual>
    <collision>
      <origin
        xyz="0 0 0"
        rpy="0 0 0" />
      <geometry>
        <mesh
          filename="../meshes/collision/left_hand_left_index_MCP_collision_Link.STL" />
      </geometry>
    </collision>
  </link>
  <joint
    name="left_index_MCP_joint"
    type="revolute">
    <origin
      xyz="5.6148E-05 -0.00097833 0.01597"
      rpy="0 0 0" />
    <parent
      link="left_index_MPR_Link" />
    <child
      link="left_index_MCP_Link" />
    <axis
      xyz="-0.05719 0.99648 0.061246" />
    <limit
      lower="-0.08727"
      upper="1.5708"
      effort="1"
      velocity="10" />
  </joint>
  <link
    name="left_index_PIP_Link">
    <inertial>
      <origin
        xyz="0.000370744874878677 -0.00104613847957594 0.0182492649545332"
        rpy="0 0 0" />
      <mass
        value="0.0332" />
      <inertia
        ixx="0.00000233"
        ixy="0.00000003"
        ixz="0.00000001"
        iyy="0.00000184"
        iyz="-0.00000003"
        izz="0.00000252" />
    </inertial>
    <visual>
      <origin
        xyz="0 0 0"
        rpy="0 0 0" />
      <geometry>
        <mesh
          filename="../meshes/left_hand_right_index_PIP_Link.STL" />
      </geometry>
    </visual>
    <collision>
      <origin
        xyz="0 0 0"
        rpy="0 0 0" />
      <geometry>
        <mesh
          filename="../meshes/collision/left_hand_left_index_PIP_collision_Link.STL" />
      </geometry>
    </collision>
  </link>
  <joint
    name="left_index_PIP_joint"
    type="revolute">
    <origin
      xyz="0.00074519 -0.0028408 0.046916"
      rpy="0 0 0" />
    <parent
      link="left_index_MCP_Link" />
    <child
      link="left_index_PIP_Link" />
    <axis
      xyz="-0.05719 0.99648 0.061246" />
    <limit
      lower="-0.17453"
      upper="1.5708"
      effort="1"
      velocity="10" />
  </joint>
  <link
    name="left_index_DIP_Link">
    <inertial>
      <origin
        xyz="-0.000423033766242854 -0.000957327735632299 0.015555232642498"
        rpy="0 0 0" />
      <mass
        value="0.01" />
      <inertia
        ixx="0.00000057"
        ixy="0.00000000"
        ixz="0.00000000"
        iyy="0.00000048"
        iyz="0.00000003"
        izz="0.00000064" />
    </inertial>
    <visual>
      <origin
        xyz="0 0 0"
        rpy="0 0 0" />
      <geometry>
        <mesh
          filename="../meshes/left_hand_right_index_DIP_Link.STL" />
      </geometry>
    </visual>
    <collision>
      <origin
        xyz="0 0 0"
        rpy="0 0 0" />
      <geometry>
        <mesh
          filename="../meshes/collision/left_hand_left_index_DIP_collision_Link.STL" />
      </geometry>
    </collision>
  </link>
  <joint
    name="left_index_DIP_joint"
    type="revolute">
    <origin
      xyz="0.0013649 -0.0017312 0.029441"
      rpy="0 0 0" />
    <parent
      link="left_index_PIP_Link" />
    <child
      link="left_index_DIP_Link" />
    <axis
      xyz="-0.05719 0.99648 0.061246" />
    <limit
      lower="-0.2618"
      upper="1.5708"
      effort="1"
      velocity="10" />
  </joint>
  <link
    name="left_index_tip_Link">
    <inertial>
      <origin
        xyz="-1.79076716411326E-07 -2.20261967755209E-07 -7.01988050744173E-08"
        rpy="0 0 0" />
      <mass
        value="5.23598775598299E-07" />
      <inertia
        ixx="0.00000064"
        ixy="0"
        ixz="0.00000003"
        iyy="0.00000057"
        iyz="0"
        izz="0.00000048" />
    </inertial>
    <visual>
      <origin
        xyz="0 0 0"
        rpy="0 0 0" />
      <geometry>
        <mesh
          filename="../meshes/left_hand_right_index_tip_Link.STL" />
      </geometry>
    </visual>
    <!-- <collision>
      <origin
        xyz="0 0 0"
        rpy="0 0 0" />
      <geometry>
        <mesh
          filename="../meshes/left_hand_right_index_tip_Link.STL" />
      </geometry>
    </collision> -->
  </link>
  <joint
    name="left_index_tip_joint"
    type="fixed">
    <origin
      xyz="-0.00427663410809782 -0.002118893232875 0.0304813148883382"
      rpy="0 0 0" />
    <parent
      link="left_index_DIP_Link" />
    <child
      link="left_index_tip_Link" />
    <axis
      xyz="0 0 0" />
  </joint>
  <link
    name="left_middle_MPR_Link">
    <inertial>
      <origin
        xyz="-0.00226234745949089 -0.00041200416235287 0.00543626728363583"
        rpy="0 0 0" />
      <mass
        value="0.013" />
      <inertia
    ixx="0.00000042"
        ixy="0"
        ixz="0"
        iyy="0.00000042"
        iyz="0"
        izz="0.00000042" />
    </inertial>
    <visual>
      <origin
        xyz="0 0 0"
        rpy="0 0 0" />
      <geometry>
        <mesh
          filename="../meshes/left_hand_right_middle_MPR_Link.STL" />
      </geometry>
    </visual>
    <collision>
      <origin
        xyz="0 0 0"
        rpy="0 0 0" />
      <geometry>
        <mesh
          filename="../meshes/collision/left_hand_left_middle_MPR_collision_Link.STL" />
      </geometry>
    </collision>
  </link>
  <joint
    name="left_middle_MPR_joint"
    type="revolute">
    <origin
      xyz="-0.0060223 -0.012496 0.10793"
      rpy="0 0 0" />
    <parent
      link="left_hand_base_link" />
    <child
      link="left_middle_MPR_Link" />
    <axis
      xyz="-0.99982 0.019105 0" />
    <limit
      lower="-0.2618"
      upper="0.2618"
      effort="1"
      velocity="10" />
  </joint>
  <link
    name="left_middle_MCP_Link">
    <inertial>
      <origin
        xyz="-9.5838057758371E-05 -0.000470960883771738 0.022947121697826"
        rpy="0 0 0" />
      <mass
        value="0.0658" />
      <inertia
        ixx="0.00001167"
        ixy="-0.00000014"
        ixz="-0.00000003"
        iyy="0.00000374"
        iyz="0.00000003"
        izz="0.00001192" />
    </inertial>
    <visual>
      <origin
        xyz="0 0 0"
        rpy="0 0 0" />
      <geometry>
        <mesh
          filename="../meshes/left_hand_right_middle_MCP_Link.STL" />
      </geometry>
    </visual>
    <collision>
      <origin
        xyz="0 0 0"
        rpy="0 0 0" />
      <geometry>
        <mesh
          filename="../meshes/collision/left_hand_left_middle_MCP_collision_Link.STL" />
      </geometry>
    </collision>
  </link>
  <joint
    name="left_middle_MCP_joint"
    type="revolute">
    <origin
      xyz="0 -0.00032687 0.015997"
      rpy="0 0 0" />
    <parent
      link="left_middle_MPR_Link" />
    <child
      link="left_middle_MCP_Link" />
    <axis
      xyz="-0.019101 0.99961 0.020433" />
    <limit
      lower="-0.08727"
      upper="1.5708"
      effort="1"
      velocity="10" />
  </joint>
  <link
    name="left_middle_PIP_Link">
    <inertial>
      <origin
        xyz="0.0003162445952244 -0.000313518881927065 0.0182775612509023"
        rpy="0 0 0" />
      <mass
        value="0.0332" />
      <inertia
        ixx="0.00000233"
        ixy="0"
        ixz="0"
        iyy="-0.00000183"
        iyz="-0.00000003"
        izz="0.00000252" />
    </inertial>
    <visual>
      <origin
        xyz="0 0 0"
        rpy="0 0 0" />
      <geometry>
        <mesh
          filename="../meshes/left_hand_right_middle_PIP_Link.STL" />
      </geometry>
    </visual>
    <collision>
      <origin
        xyz="0 0 0"
        rpy="0 0 0" />
      <geometry>
        <mesh
          filename="../meshes/collision/left_hand_left_middle_PIP_collision_Link.STL" />
      </geometry>
    </collision>
  </link>
  <joint
    name="left_middle_PIP_joint"
    type="revolute">
    <origin
      xyz="0.00059944 -0.00094917 0.046994"
      rpy="0 0 0" />
    <parent
      link="left_middle_MCP_Link" />
    <child
      link="left_middle_PIP_Link" />
    <axis
      xyz="-0.019101 0.99961 0.020433" />
    <limit
      lower="-0.17453"
      upper="1.5708"
      effort="1"
      velocity="10" />
  </joint>
  <link
    name="left_middle_DIP_Link">
    <inertial>
      <origin
        xyz="-0.000471213636152063 -0.000305084708637014 0.0155807760832885"
        rpy="0 0 0" />
      <mass
        value="0.01" />
      <inertia
        ixx="0.00000057"
        ixy="0"
        ixz="0"
        iyy="0.00000048"
        iyz="0.00000003"
        izz="0.00000064" />
    </inertial>
    <visual>
      <origin
        xyz="0 0 0"
        rpy="0 0 0" />
      <geometry>
        <mesh
          filename="../meshes/left_hand_right_middle_DIP_Link.STL" />
      </geometry>
    </visual>
    <collision>
      <origin
        xyz="0 0 0"
        rpy="0 0 0" />
      <geometry>
        <mesh
          filename="../meshes/collision/left_hand_left_middle_DIP_collision_Link.STL" />
      </geometry>
    </collision>
  </link>
  <joint
    name="left_middle_DIP_joint"
    type="revolute">
    <origin
      xyz="0.0012747 -0.00057846 0.02949"
      rpy="0 0 0" />
    <parent
      link="left_middle_PIP_Link" />
    <child
      link="left_middle_DIP_Link" />
    <axis
      xyz="-0.019101 0.99961 0.020433" />
    <limit
      lower="-0.2618"
      upper="1.5708"
      effort="1"
      velocity="10" />
  </joint>
  <link
    name="left_middle_tip_Link">
    <inertial>
      <origin
        xyz="-1.87311433013509E-07 -2.15949397431789E-07 -6.15789047253568E-08"
        rpy="0 0 0" />
      <mass
        value="5.23598775598299E-07" />
      <inertia
        ixx="5.23598775598299E-14"
        ixy="2.49959963776976E-46"
        ixz="0"
        iyy="5.23598775598299E-14"
        iyz="2.77511307019669E-62"
        izz="5.23598775598299E-14" />
    </inertial>
    <visual>
      <origin
        xyz="0 0 0"
        rpy="0 0 0" />
      <geometry>
        <mesh
          filename="../meshes/left_hand_right_middle_tip_Link.STL" />
      </geometry>
    </visual>
    <!-- <collision>
      <origin
        xyz="0 0 0"
        rpy="0 0 0" />
      <geometry>
        <mesh
          filename="../meshes/left_hand_right_middle_tip_Link.STL" />
      </geometry>
    </collision> -->
  </link>
  <joint
    name="left_middle_tip_joint"
    type="fixed">
    <origin
      xyz="-0.00437829209467304 -0.000707780837012447 0.0305322693190233"
      rpy="0 0 0" />
    <parent
      link="left_middle_DIP_Link" />
    <child
      link="left_middle_tip_Link" />
    <axis
      xyz="0 0 0" />
  </joint>
  <link
    name="left_ring_MPR_Link">
    <inertial>
      <origin
        xyz="-0.00227218644192482 -0.00010288825584872 0.00544680007348868"
        rpy="0 0 0" />
      <mass
        value="0.013" />
      <inertia
        ixx="0.00000042"
        ixy="0"
        ixz="0"
        iyy="0.00000042"
        iyz="0"
        izz="0.00000042" />
    </inertial>
    <visual>
      <origin
        xyz="0 0 0"
        rpy="0 0 0" />
      <geometry>
        <mesh
          filename="../meshes/left_hand_right_ring_MPR_Link.STL" />
      </geometry>
    </visual>
    <collision>
      <origin
        xyz="0 0 0"
        rpy="0 0 0" />
      <geometry>
        <mesh
          filename="../meshes/collision/left_hand_left_ring_MPR_collision_Link.STL" />
      </geometry>
    </collision>
  </link>
  <joint
    name="left_ring_MPR_joint"
    type="revolute">
    <origin
      xyz="-0.0061966 0.012414 0.10384"
      rpy="0 0 0" />
    <parent
      link="left_hand_base_link" />
    <child
      link="left_ring_MPR_Link" />
    <axis
      xyz="-0.99982 -0.019105 0" />
    <limit
      lower="-0.2618"
      upper="0.2618"
      effort="1"
      velocity="10" />
  </joint>
  <link
    name="left_ring_MCP_Link">
    <inertial>
      <origin
        xyz="-9.58428511951045E-05 0.000470834699675895 0.0229471117809421"
        rpy="0 0 0" />
      <mass
        value="0.0658" />
      <inertia
        ixx="0.00001166"
        ixy="-0.00000016"
        ixz="0"
        iyy="0.00000374"
        iyz="0.00000003"
        izz="0.00001192" />
    </inertial>
    <visual>
      <origin
        xyz="0 0 0"
        rpy="0 0 0" />
      <geometry>
        <mesh
          filename="../meshes/left_hand_right_ring_MCP_Link.STL" />
      </geometry>
    </visual>
    <collision>
      <origin
        xyz="0 0 0"
        rpy="0 0 0" />
      <geometry>
        <mesh
          filename="../meshes/collision/left_hand_left_ring_MCP_collision_Link.STL" />
      </geometry>
    </collision>
  </link>
  <joint
    name="left_ring_MCP_joint"
    type="revolute">
    <origin
      xyz="0 0.00032687 0.015997"
      rpy="0 0 0" />
    <parent
      link="left_ring_MPR_Link" />
    <child
      link="left_ring_MCP_Link" />
    <axis
      xyz="0.019101 0.99961 -0.020433" />
    <limit
      lower="-0.08727"
      upper="1.5708"
      effort="1"
      velocity="10" />
  </joint>
  <link
    name="left_ring_PIP_Link">
    <inertial>
      <origin
        xyz="0.000318318311485932 0.000421541699007098 0.0182753474260187"
        rpy="0 0 0" />
      <mass
        value="0.0332" />
      <inertia
        ixx="0.00000233"
        ixy="0"
        ixz="0"
        iyy="0.00000183"
        iyz="-0.00000003"
        izz="0.00000252" />
    </inertial>
    <visual>
      <origin
        xyz="0 0 0"
        rpy="0 0 0" />
      <geometry>
        <mesh
          filename="../meshes/left_hand_right_ring_PIP_Link.STL" />
      </geometry>
    </visual>
    <collision>
      <origin
        xyz="0 0 0"
        rpy="0 0 0" />
      <geometry>
        <mesh
          filename="../meshes/collision/left_hand_left_ring_PIP_collision_Link.STL" />
      </geometry>
    </collision>
  </link>
  <joint
    name="left_ring_PIP_joint"
    type="revolute">
    <origin
      xyz="0.00059944 0.00094917 0.046994"
      rpy="0 0 0" />
    <parent
      link="left_ring_MCP_Link" />
    <child
      link="left_ring_PIP_Link" />
    <axis
      xyz="0.019101 0.99961 -0.020433" />
    <limit
      lower="-0.17453"
      upper="1.5708"
      effort="1"
      velocity="10" />
  </joint>
  <link
    name="left_ring_DIP_Link">
    <inertial>
      <origin
        xyz="-0.000470371825634083 0.000349335106693119 0.0155798701552171"
        rpy="0 0 0" />
      <mass
        value="0.01" />
      <inertia
        ixx="0.00000057"
        ixy="0"
        ixz="0"
        iyy="0.00000048"
        iyz="0.00000003"
        izz="0.00000064" />
    </inertial>
    <visual>
      <origin
        xyz="0 0 0"
        rpy="0 0 0" />
      <geometry>
        <mesh
          filename="../meshes/left_hand_right_ring_DIP_Link.STL" />
      </geometry>
    </visual>
    <collision>
      <origin
        xyz="0 0 0"
        rpy="0 0 0" />
      <geometry>
        <mesh
          filename="../meshes/collision/left_hand_left_ring_DIP_collision_Link.STL" />
      </geometry>
    </collision>
  </link>
  <joint
    name="left_ring_DIP_joint"
    type="revolute">
    <origin
      xyz="0.0012747 0.00057846 0.02949"
      rpy="0 0 0" />
    <parent
      link="left_ring_PIP_Link" />
    <child
      link="left_ring_DIP_Link" />
    <axis
      xyz="0.019101 0.99961 -0.020433" />
    <limit
      lower="-0.2618"
      upper="1.5708"
      effort="1"
      velocity="10" />
  </joint>
  <link
    name="left_ring_tip_Link">
    <inertial>
      <origin
        xyz="-2.02102413745381E-07 -5.58358974975942E-07 -4.57613862914208E-08"
        rpy="0 0 0" />
      <mass
        value="5.23598775598299E-07" />
      <inertia
        ixx="5.23598775598299E-14"
        ixy="2.49959963776976E-46"
        ixz="0"
        iyy="5.23598775598299E-14"
        iyz="2.77511307019669E-62"
        izz="5.23598775598299E-14" />
    </inertial>
    <visual>
      <origin
        xyz="0 0 0"
        rpy="0 0 0" />
      <geometry>
        <mesh
          filename="../meshes/left_hand_right_ring_tip_Link.STL" />
      </geometry>
    </visual>
    <!-- <collision>
      <origin
        xyz="0 0 0"
        rpy="0 0 0" />
      <geometry>
        <mesh
          filename="../meshes/left_hand_right_ring_tip_Link.STL" />
      </geometry>
    </collision> -->
  </link>
  <joint
    name="left_ring_tip_joint"
    type="fixed">
    <origin
      xyz="-0.00437829209467306 0.000707780837011795 0.0305322693190233"
      rpy="0 0 0" />
    <parent
      link="left_ring_DIP_Link" />
    <child
      link="left_ring_tip_Link" />
    <axis
      xyz="0 0 0" />
  </joint>
  <link
    name="left_little_MPR_Link">
    <inertial>
      <origin
        xyz="-0.00226172289791385 0.00020620363238872 0.00544823682755248"
        rpy="0 0 0" />
      <mass
        value="0.013" />
      <inertia
        ixx="0.00000042"
        ixy="0"
        ixz="0"
        iyy="0.00000042"
        iyz="0"
        izz="0.00000042" />
    </inertial>
    <visual>
      <origin
        xyz="0 0 0"
        rpy="0 0 0" />
      <geometry>
        <mesh
          filename="../meshes/left_hand_right_little_MPR_Link.STL" />
      </geometry>
    </visual>
    <collision>
      <origin
        xyz="0 0 0"
        rpy="0 0 0" />
      <geometry>
        <mesh
          filename="../meshes/collision/left_hand_left_little_MPR_collision_Link.STL" />
      </geometry>
    </collision>
  </link>
  <joint
    name="left_little_MPR_joint"
    type="revolute">
    <origin
      xyz="-0.0052198 0.036409 0.090532"
      rpy="0 0 0" />
    <parent
      link="left_hand_base_link" />
    <child
      link="left_little_MPR_Link" />
    <axis
      xyz="-0.99836 -0.057297 0" />
    <limit
      lower="-0.2618"
      upper="0.2618"
      effort="1"
      velocity="10" />
  </joint>
  <link
    name="left_little_MCP_Link">
    <inertial>
      <origin
        xyz="-2.41194481714968E-05 0.00140935520774608 0.0229088910138511"
        rpy="0 0 0" />
      <mass
        value="0.0658" />
      <inertia
        ixx="0.00001164"
        ixy="-0.00000049"
        ixz="-0.00000001"
        iyy="0.00000376"
        iyz="0"
        izz="0.00001192" />
    </inertial>
    <visual>
      <origin
        xyz="0 0 0"
        rpy="0 0 0" />
      <geometry>
        <mesh
          filename="../meshes/left_hand_right_little_MCP_Link.STL" />
      </geometry>
    </visual>
    <collision>
      <origin
        xyz="0 0 0"
        rpy="0 0 0" />
      <geometry>
        <mesh
          filename="../meshes/collision/left_hand_left_little_MCP_collision_Link.STL" />
      </geometry>
    </collision>
  </link>
  <joint
    name="left_little_MCP_joint"
    type="revolute">
    <origin
      xyz="5.6148E-05 0.00097833 0.01597"
      rpy="0 0 0" />
    <parent
      link="left_little_MPR_Link" />
    <child
      link="left_little_MCP_Link" />
    <axis
      xyz="0.05719 0.99648 -0.061246" />
    <limit
      lower="-0.08727"
      upper="1.5708"
      effort="1"
      velocity="10" />
  </joint>
  <link
    name="left_little_PIP_Link">
    <inertial>
      <origin
        xyz="0.000376933372389854 0.00115382483744118 0.0182426388313639"
        rpy="0 0 0" />
      <mass
        value="0.0332" />
      <inertia
        ixx="0.00000233"
        ixy="-0.00000003"
        ixz="-0.00000001"
        iyy="0.00000184"
        iyz="-0.00000003"
        izz="0.00000252" />
    </inertial>
    <visual>
      <origin
        xyz="0 0 0"
        rpy="0 0 0" />
      <geometry>
        <mesh
          filename="../meshes/left_hand_right_little_PIP_Link.STL" />
      </geometry>
    </visual>
    <collision>
      <origin
        xyz="0 0 0"
        rpy="0 0 0" />
      <geometry>
        <mesh
          filename="../meshes/collision/left_hand_left_little_PIP_collision_Link.STL" />
      </geometry>
    </collision>
  </link>
  <joint
    name="left_little_PIP_joint"
    type="revolute">
    <origin
      xyz="0.00074519 0.0028408 0.046916"
      rpy="0 0 0" />
    <parent
      link="left_little_MCP_Link" />
    <child
      link="left_little_PIP_Link" />
    <axis
      xyz="0.05719 0.99648 -0.061246" />
    <limit
      lower="-0.17453"
      upper="1.5708"
      effort="1"
      velocity="10" />
  </joint>
  <link
    name="left_little_DIP_Link">
    <inertial>
      <origin
        xyz="-0.00042050820163792 0.00100142802177363 0.0155525202704654"
        rpy="0 0 0" />
      <mass
        value="0.01" />
      <inertia
        ixx="0.00000057"
        ixy="0"
        ixz="0.00000048"
        iyy="0.00000003"
        iyz="0"
        izz="0.00000064" />
    </inertial>
    <visual>
      <origin
        xyz="0 0 0"
        rpy="0 0 0" />
      <geometry>
        <mesh
          filename="../meshes/left_hand_right_little_DIP_Link.STL" />
      </geometry>
    </visual>
    <collision>
      <origin
        xyz="0 0 0"
        rpy="0 0 0" />
      <geometry>
        <mesh
          filename="../meshes/collision/left_hand_left_little_DIP_collision_Link.STL" />
      </geometry>
    </collision>
  </link>
  <joint
    name="left_little_DIP_joint"
    type="revolute">
    <origin
      xyz="0.0013649 0.0017312 0.029441"
      rpy="0 0 0" />
    <parent
      link="left_little_PIP_Link" />
    <child
      link="left_little_DIP_Link" />
    <axis
      xyz="0.05719 0.99648 -0.061246" />
    <limit
      lower="-0.2618"
      upper="1.5708"
      effort="1"
      velocity="10" />
  </joint>
  <link
    name="left_little_tip_Link">
    <inertial>
      <origin
        xyz="-2.03501966271336E-07 -2.05327846648784E-07 -4.40410908020272E-08"
        rpy="0 0 0" />
      <mass
        value="5.23598775598299E-07" />
      <inertia
        ixx="5.23598775598299E-14"
        ixy="2.49959963776976E-46"
        ixz="0"
        iyy="5.23598775598299E-14"
        iyz="2.77511307019669E-62"
        izz="5.23598775598299E-14" />
    </inertial>
    <visual>
      <origin
        xyz="0 0 0"
        rpy="0 0 0" />
      <geometry>
        <mesh
          filename="../meshes/left_hand_right_little_tip_Link.STL" />
      </geometry>
    </visual>
    <!-- <collision>
      <origin
        xyz="0 0 0"
        rpy="0 0 0" />
      <geometry>
        <mesh
          filename="../meshes/left_hand_right_little_tip_Link.STL" />
      </geometry>
    </collision> -->
  </link>
  <joint
    name="left_little_tip_joint"
    type="fixed">
    <origin
      xyz="-0.00427663410809784 0.00211889323287445 0.0304813148883381"
      rpy="0 0 0" />
    <parent
      link="left_little_DIP_Link" />
    <child
      link="left_little_tip_Link" />
    <axis
      xyz="0 0 0" />
  </joint>
</robot>
